Workbook

Sheet Original Source
A1: Date | B1: Financials | C1: Amount
A2: 1.1.2014 | B2: Revenue - Supermarkets | C2: 72
A3: 1.1.2014 | B3: Cogs - Supermarkets | C3: 47
A4: 1.1.2014 | B4: Revenue - Discounters | C4: 37
A5: 1.1.2014 | B5: Cogs - Discounters | C5: 20
A6: 1.1.2014 | B6: Revenue - Grocery | C6: 36
A7: 1.1.2014 | B7: Cogs - Grocery | C7: 17
A8: 1.1.2014 | B8: Revenue - Retail | C8: 57
A9: 1.1.2014 | B9: Cogs - Retail | C9: 32
A10: 1.1.2014 | B10: Operating expenses | C10: 95.4
A11: 1.1.2014 | B11: D&A | C11: 2
A12: 1.1.2014 | B12: Interest expenses | C12: 5
A13: 1.1.2014 | B13: Taxes | C13: 17.29
... A436: 12.1.2016 | B436: Other revenue | C436: 628

Sheet BS 2014
B1: $ in mln | D1: 42004
B2: Receivables - Discounters | D2: 44.609
B3: Receivables - Other | D3: 33.097
B4: Receivables - Grocery | D4: 31.658
B5: Receivables - Retail | D5: 20.146
B6: Receivables - Supermarkets | D6: 14.39
B7: Trade Receivables | D7: 143.9
B8: Inventory - Discounters | D8: 29.75
B9: Inventory - Supermarkets | D9: 18.7
B10: Inventory - Grocery | D10: 16.15
B11: Inventory - Retail | D11: 11.05
B12: Inventory - Other | D12: 9.35
... B23: Other assets | D23: 45.9
B24: Other assets | D24: 45.9 | F24: =B24=B23 -> TRUE
B25: Assets | D25: 932.1
B26: Trade Payables - Discounters | D26: 17
B27: Trade Payables - Other | D27: 17
B28: Trade Payables - Supermarkets | D28: 14.96
B29: Trade Payables - Grocery | D29: 10.2
B30: Trade Payables - Retail | D30: 8.84
B31: Trade Payables | D31: 68
B32: Provisions - Taxes | D32: 22.425
B33: Provisions - Legal | D33: 6.825
B34: Provisions - Other | D34: 3.25
B35: Provisions | D35: 32.5
B36: Financial Liabilities vs. Banks | D36: 615.8
... B44: Liabilities & Equity | D44: 932.1

Sheet BS 2015
B1: $ in mln | C1: Code I | D1: 42369
B2: Receivables - Discounters | C2: R | D2: 40.248
B3: Receivables - Grocery | C3: R | D3: 34.056
B4: Receivables - Other | C4: R | D4: 29.412
B5: Receivables - Retail | C5: R | D5: 27.864
B6: Receivables - Supermarkets | C6: R | D6: 23.22
B7: Trade Receivables | D7: 154.8
B9: Inventory - Discounters | C9: I | D9: 24.84
B10: Inventory - Supermarkets | C10: I | D10: 20.24
B11: Inventory - Grocery | C11: I | D11: 17.48
B12: Inventory - Other | C12: I | D12: 17.48
B13: Inventory - Retail | C13: I | D13: 11.96
B14: Inventory | C14: I | D14: 92
B16: PP&E - Machinery | C16: P | D16: 346.475
B17: PP&E - Other | C17: P | D17: 139.525
B18: PP&E - IT | C18: P | D18: 125.575
B19: PP&E - Vehicles | C19: P | D19: 20.925
B20: PP&E | C20: P | D20: 632.5
B22: Cash - Bank Accounts | C22: C | D22: 13.298
... B24: Cash - Cash at hand | C24: C | D24: 3.052
B25: Cash | D25: 21.8
B27: Other assets | C27: O | D27: 46.9
B28: Other assets | D28: 46.9
B30: Assets | D30: 948
B32: Trade Payables - Discounters | C32: T | D32: 19.981
B33: Trade Payables - Retail | C33: T | D33: 15.847
B34: Trade Payables - Other | C34: T | D34: 14.469
B35: Trade Payables - Grocery | C35: T | D35: 10.335
B36: Trade Payables - Supermarkets | C36: T | D36: 8.268
B37: Trade Payables | D37: 68.9
B39: Provisions - Taxes | C39: P | D39: 17.507
B40: Provisions - Legal | C40: P | D40: 6.601
B41: Provisions - Other | C41: P | D41: 4.592
B42: Provisions | D42: 28.7
B44: Financial Liabilities vs. Banks | C44: F | D44: 610.4
B45: Financial Liabilities | D45: 610.4
B47: Other liabilities | C47: O | D47: 43.3
B48: Other liabilities | D48: 43.3
B50: Retained Earnings | C50: E | D50: 161.525
B51: Minority interest | C51: E | D51: 18.425
...

Sheet BS 2016
B1: $ in mln | C1: Code I | D1: Code II | E1: 42735
B2: Receivables - Discounters | C2: R | D2: A | E2: 44.018
B3: Receivables - Grocery | C3: R | D3: A | E3: 40.632
B4: Receivables - Other | C4: R | D4: A | E4: 32.167
B5: Receivables - Retail | C5: R | D5: A | E5: 27.088
B6: Receivables - Supermarkets | C6: R | D6: A | E6: 25.395
B7: Trade Receivables | E7: 169.3
B9: Inventory - Discounters | C9: I | D9: A | E9: 26.4
B10: Inventory - Supermarkets | C10: I | D10: A | E10: 25.3
B11: Inventory - Grocery | C11: I | D11: A | E11: 20.9
B12: Inventory - Other | C12: I | D12: A | E12: 20.9
B13: Inventory - Retail | C13: I | D13: A | E13: 16.5
B14: Inventory | C14: I | E14: 110
B16: PP&E - Machinery | C16: P | D16: A | E16: 350.51
B17: PP&E - Other | C17: P | D17: A | E17: 146.71
B18: PP&E - IT | C18: P | D18: A | E18: 133.735
B19: PP&E - Vehicles | C19: P | D19: A | E19: 28.545
B20: PP&E | E20: 659.5
B22: Cash - Bank Accounts | C22: C | D22: A | E22: 125.4
B23: Cash - T-bills | C23: C | D23: A | E23: 59.4
B24: Cash - Cash at hand | C24: C | D24: A | E24: 35.2
B25: Cash | E25: 220
B27: Other assets | C27: O | D27: A | E27: 68
B28: Other assets | E28: 68
B30: Assets | E30: 1226.8
B32: Trade Payables - Discounters | C32: T | D32: L | E32: 19.981
B33: Trade Payables - Retail | C33: T | D33: L | E33: 15.847
B34: Trade Payables - Other | C34: T | D34: L | E34: 14.469
B35: Trade Payables - Grocery | C35: T | D35: L | E35: 10.335
B36: Trade Payables - Supermarkets | C36: T | D36: L | E36: 8.268
B37: Trade Payables | E37: 68.9
B39: Provisions - Taxes | C39: P | D39: L | E39: 17.507
B40: Provisions - Legal | C40: P | D40: L | E40: 6.601
B41: Provisions - Other | C41: P | D41: L | E41: 4.592
B42: Provisions | E42: 28.7
B44: Financial Liabilities vs. Banks | C44: F | D44: L | E44: 605
B45: Financial Liabilities | E45: 605
B47: Other liabilities | C47: O | D47: L | E47: 38.9
B48: Other liabilities | E48: 38.9
B50: Retained Earnings | C50: E | D50: E | E50: 450.125
...

Sheet Exercise -->
B13: Exercise -->

Sheet Workings
A1: Date | B1: Year | C1: Financials | D1: Amount | E1: Mapping
A2: 41640 | B2: =YEAR(A2) -> 2014 | C2: Revenue - Supermarkets | D2: 72 | E2: Revenue
A3: 41640 | B3: =YEAR(A3) -> 2014 | C3: Cogs - Supermarkets | D3: 47 | E3: Cost of goods sold
A4: 41640 | B4: =YEAR(A4) -> 2014 | C4: Revenue - Discounters | D4: 37 | E4: Revenue
A5: 41640 | B5: =YEAR(A5) -> 2014 | C5: Cogs - Discounters | D5: 20 | E5: Cost of goods sold
A6: 41640 | B6: =YEAR(A6) -> 2014 | C6: Revenue - Grocery | D6: 36 | E6: Revenue
A7: 41640 | B7: =YEAR(A7) -> 2014 | C7: Cogs - Grocery | D7: 17 | E7: Cost of goods sold
A8: 41640 | B8: =YEAR(A8) -> 2014 | C8: Revenue - Retail | D8: 57 | E8: Revenue
A9: 41640 | B9: =YEAR(A9) -> 2014 | C9: Cogs - Retail | D9: 32 | E9: Cost of goods sold
A10: 41640 | B10: =YEAR(A10) -> 2014 | C10: Operating expenses | D10: 95.4 | E10: Operating expenses
A11: 41640 | B11: =YEAR(A11) -> 2014 | C11: D&A | D11: 2 | E11: D&A
A12: 41640 | B12: =YEAR(A12) -> 2014 | C12: Interest expenses | D12: 5 | E12: Interest expenses
A13: 41640 | B13: =YEAR(A13) -> 2014 | C13: Taxes | D13: 17.29 | E13: Taxes
... A436: 42705 | B436: =YEAR(A436) -> 2016 | C436: Other revenue | D436: 628 | E436: Revenue

Sheet P&L
B1: P&L
B2: Scenario | C2: Base Case
I3: Forecast
B4: $ in million | C4: 2014 | D4: 2015 | E4: 2016 | G4: Var % 14-15 | H4: Var % 15-16 | I4: 2017 | J4: 2018 | K4: 2019 | L4: 2020 | M4: 2021
B5: Revenue | C5: =+SUMIFS(Workings!$D:$D,Workings!$E:$E,'P&L'!$B5,Workings!$B:$B,'P&L'!C$4) -> 2922 | D5: =+SUMIFS(Workings!$D:$D,Workings!$E:$E,'P&L'!$B5,Workings!$B:$B,'P&L'!D$4) -> 2984 | E5: =+SUMIFS(Workings!$D:$D,Workings!$E:$E,'P&L'!$B5,Workings!$B:$B,'P&L'!E$4) -> 3040 | G5: =D5/C5-1 -> 0.021218344 | H5: =E5/D5-1 -> 0.018766756 | I5: =E5+(E5*I20) -> 3100.8 | J5: =I5*(1+J20) -> 3162.816 | K5: =J5*(1+K20) -> 3226.0723 | L5: =K5*(1+L20) -> 3290.5938 | M5: =L5*(1+M20) -> 3356.4056
B6: Cost of goods sold | C6: =-1*SUMIFS(Workings!$D:$D,Workings!$E:$E,'P&L'!$B6,Workings!$B:$B,'P&L'!C$4) -> -1401 | D6: =-1*SUMIFS(Workings!$D:$D,Workings!$E:$E,'P&L'!$B6,Workings!$B:$B,'P&L'!D$4) -> -1383 | E6: =-1*SUMIFS(Workings!$D:$D,Workings!$E:$E,'P&L'!$B6,Workings!$B:$B,'P&L'!E$4) -> -1367 | G6: =D6/C6-1 -> -0.012847966 | H6: =E6/D6-1 -> -0.011569053 | I6: =I5*I26 -> -1437.1335 | J6: =J5*J26 -> -1465.8762 | K6: =K5*K26 -> -1495.1937 | L6: =L5*L26 -> -1525.0976 | M6: =M5*M26 -> -1555.5995
B7: Gross Profit | C7: =SUM(C5:C6) -> 1521 | D7: =SUM(D5:D6) -> 1601 | E7: =SUM(E5:E6) -> 1673 | G7: =D7/C7-1 -> 0.052596976 | H7: =E7/D7-1 -> 0.044971893 | I7: =SUM(I5:I6) -> 1663.6665 | J7: =SUM(J5:J6) -> 1696.9398 | K7: =SUM(K5:K6) -> 1730.8786 | L7: =SUM(L5:L6) -> 1765.4962 | M7: =SUM(M5:M6) -> 1800.8061
B8: Operating expenses | C8: =-1*SUMIFS(Workings!$D:$D,Workings!$E:$E,'P&L'!$B8,Workings!$B:$B,'P&L'!C$4) -> -1212.18 | D8: =-1*SUMIFS(Workings!$D:$D,Workings!$E:$E,'P&L'!$B8,Workings!$B:$B,'P&L'!D$4) -> -1245.34 | E8: =-1*SUMIFS(Workings!$D:$D,Workings!$E:$E,'P&L'!$B8,Workings!$B:$B,'P&L'!E$4) -> -1068.24 | G8: =D8/C8-1 -> 0.027355673 | H8: =E8/D8-1 -> -0.14221016 | I8: =I5*I31 -> -1286.3545 | J8: =J5*J31 -> -1312.0816 | K8: =K5*K31 -> -1338.3232 | L8: =L5*L31 -> -1365.0896 | M8: =M5*M31 -> -1392.3914
B9: EBITDA | C9: =SUM(C7:C8) -> 308.82 | D9: =SUM(D7:D8) -> 355.66 | E9: =SUM(E7:E8) -> 604.76 | G9: =D9/C9-1 -> 0.15167411 | H9: =E9/D9-1 -> 0.70038801 | I9: =SUM(I7:I8) -> 377.31202 | J9: =SUM(J7:J8) -> 384.85826 | K9: =SUM(K7:K8) -> 392.55543 | L9: =SUM(L7:L8) -> 400.40654 | M9: =SUM(M7:M8) -> 408.41467
B10: D&A | C10: =-1*SUMIFS(Workings!$D:$D,Workings!$E:$E,'P&L'!$B10,Workings!$B:$B,'P&L'!C$4) -> -31 | D10: =-1*SUMIFS(Workings!$D:$D,Workings!$E:$E,'P&L'!$B10,Workings!$B:$B,'P&L'!D$4) -> -44 | E10: =-1*SUMIFS(Workings!$D:$D,Workings!$E:$E,'P&L'!$B10,Workings!$B:$B,'P&L'!E$4) -> -41 | G10: =D10/C10-1 -> 0.41935484 | H10: =E10/D10-1 -> -0.068181818 | I10: ='Fixed Asset Roll Forward'!F5 -> -44.314229 | J10: ='Fixed Asset Roll Forward'!G5 -> -45.260067 | K10: ='Fixed Asset Roll Forward'!H5 -> -46.226092 | L10: ='Fixed Asset Roll Forward'!I5 -> -47.212736 | M10: ='Fixed Asset Roll Forward'!J5 -> -48.220438
B11: EBIT | C11: =SUM(C9:C10) -> 277.82 | D11: =SUM(D9:D10) -> 311.66 | E11: =SUM(E9:E10) -> 563.76 | G11: =D11/C11-1 -> 0.12180549 | H11: =E11/D11-1 -> 0.80889431 | I11: =SUM(I9:I10) -> 332.99779 | J11: =SUM(J9:J10) -> 339.5982 | K11: =SUM(K9:K10) -> 346.32934 | L11: =SUM(L9:L10) -> 353.1938 | M11: =SUM(M9:M10) -> 360.19423
B12: Interest expenses | C12: =-1*SUMIFS(Workings!$D:$D,Workings!$E:$E,'P&L'!$B12,Workings!$B:$B,'P&L'!C$4) -> -56 | D12: =-1*SUMIFS(Workings!$D:$D,Workings!$E:$E,'P&L'!$B12,Workings!$B:$B,'P&L'!D$4) -> -65 | E12: =-1*SUMIFS(Workings!$D:$D,Workings!$E:$E,'P&L'!$B12,Workings!$B:$B,'P&L'!E$4) -> -52 | G12: =D12/C12-1 -> 0.16071429 | H12: =E12/D12-1 -> -0.2 | I12: ='Financial Liablity'!C15 -> -54.45 | J12: ='Financial Liablity'!D15 -> -50.866096 | K12: ='Financial Liablity'!E15 -> -46.959641 | L12: ='Financial Liablity'!F15 -> -42.701605 | M12: ='Financial Liablity'!G15 -> -38.060345
B13: EBT | C13: =SUM(C11:C12) -> 221.82 | D13: =SUM(D11:D12) -> 246.66 | E13: =SUM(E11:E12) -> 511.76 | G13: =D13/C13-1 -> 0.11198269 | H13: =E13/D13-1 -> 1.0747588 | I13: =SUM(I11:I12) -> 278.54779 | J13: =SUM(J11:J12) -> 288.7321 | K13: =SUM(K11:K12) -> 299.3697 | L13: =SUM(L11:L12) -> 310.4922 | M13: =SUM(M11:M12) -> 322.13389
B14: Taxes | C14: =-1*SUMIFS(Workings!$D:$D,Workings!$E:$E,'P&L'!$B14,Workings!$B:$B,'P&L'!C$4) -> -207.52 | D14: =-1*SUMIFS(Workings!$D:$D,Workings!$E:$E,'P&L'!$B14,Workings!$B:$B,'P&L'!D$4) -> -209.98 | E14: =-1*SUMIFS(Workings!$D:$D,Workings!$E:$E,'P&L'!$B14,Workings!$B:$B,'P&L'!E$4) -> -208.58 | G14: =D14/C14-1 -> 0.011854279 | H14: =E14/D14-1 -> -0.0066673016 | I14: =I13*I36 -> -97.491728 | J14: =J13*J36 -> -101.05624 | K14: =K13*K36 -> -104.77939 | L14: =L13*L36 -> -108.67227 | M14: =M13*M36 -> -112.74686
B15: Net Income | C15: =SUM(C13:C14) -> 14.3 | D15: =SUM(D13:D14) -> 36.68 | E15: =SUM(E13:E14) -> 303.18 | G15: =D15/C15-1 -> 1.565035 | H15: =E15/D15-1 -> 7.2655398 | I15: =SUM(I13:I14) -> 181.05607 | J15: =SUM(J13:J14) -> 187.67587 | K15: =SUM(K13:K14) -> 194.5903 | L15: =SUM(L13:L14) -> 201.81993 | M15: =SUM(M13:M14) -> 209.38703
B17: Scenario
B19: Revenue % growth
B20: Selected Case | I20: =CHOOSE(MATCH($C$2,$B21:$B23,0),I21,I22,I23) -> 0.02 | J20: =OFFSET(J20,MATCH($C$2,$B21:$B23,0),0) -> 0.02 | K20: =OFFSET(K20,MATCH($C$2,$B21:$B23,0),0) -> 0.02 | L20: =OFFSET(L20,MATCH($C$2,$B21:$B23,0),0) -> 0.02 | M20: =OFFSET(M20,MATCH($C$2,$B21:$B23,0),0) -> 0.02
B21: Best Case | I21: 0.03 | J21: 0.03 | K21: 0.03 | L21: 0.03 | M21: 0.03
B22: Base Case | I22: 0.02 | J22: 0.02 | K22: 0.02 | L22: 0.02 | M22: 0.02
B23: Worst Case | I23: 0.01 | J23: 0.01 | K23: 0.01 | L23: 0.01 | M23: 0.01
B25: Cogs as % Revenue
B26: Selected Case | I26: =OFFSET(I26,MATCH($C$2,$B27:$B29,0),0) -> -0.46347185 | J26: =OFFSET(J26,MATCH($C$2,$B27:$B29,0),0) -> -0.46347185 | K26: =OFFSET(K26,MATCH($C$2,$B27:$B29,0),0) -> -0.46347185 | L26: =OFFSET(L26,MATCH($C$2,$B27:$B29,0),0) -> -0.46347185 | M26: =OFFSET(M26,MATCH($C$2,$B27:$B29,0),0) -> -0.46347185
B27: Best Case | C27: =C$6/C$5 -> -0.47946612 | D27: =D$6/D$5 -> -0.46347185 | E27: =E$6/E$5 -> -0.44967105 | I27: =_xlfn.QUARTILE.EXC($C27:$E27,3) -> -0.44967105 | J27: =_xlfn.QUARTILE.EXC($C27:$E27,3) -> -0.44967105 | K27: =_xlfn.QUARTILE.EXC($C27:$E27,3) -> -0.44967105 | L27: =_xlfn.QUARTILE.EXC($C27:$E27,3) -> -0.44967105 | M27: =_xlfn.QUARTILE.EXC($C27:$E27,3) -> -0.44967105
B28: Base Case | C28: =C$6/C$5 -> -0.47946612 | D28: =D$6/D$5 -> -0.46347185 | E28: =E$6/E$5 -> -0.44967105 | I28: =_xlfn.QUARTILE.EXC($C28:$E28,2) -> -0.46347185 | J28: =_xlfn.QUARTILE.EXC($C28:$E28,2) -> -0.46347185 | K28: =_xlfn.QUARTILE.EXC($C28:$E28,2) -> -0.46347185 | L28: =_xlfn.QUARTILE.EXC($C28:$E28,2) -> -0.46347185 | M28: =_xlfn.QUARTILE.EXC($C28:$E28,2) -> -0.46347185
B29: Worst Case | C29: =C$6/C$5 -> -0.47946612 | D29: =D$6/D$5 -> -0.46347185 | E29: =E$6/E$5 -> -0.44967105 | I29: =_xlfn.QUARTILE.EXC($C29:$E29,1) -> -0.47946612 | J29: =_xlfn.QUARTILE.EXC($C29:$E29,1) -> -0.47946612 | K29: =_xlfn.QUARTILE.EXC($C29:$E29,1) -> -0.47946612 | L29: =_xlfn.QUARTILE.EXC($C29:$E29,1) -> -0.47946612 | M29: =_xlfn.QUARTILE.EXC($C29:$E29,1) -> -0.47946612
B31: Opex as % of revenue | I31: =OFFSET(I31,MATCH($C$2,$B32:$B34,0),0) -> -0.414846 | J31: =OFFSET(J31,MATCH($C$2,$B32:$B34,0),0) -> -0.414846 | K31: =OFFSET(K31,MATCH($C$2,$B32:$B34,0),0) -> -0.414846 | L31: =OFFSET(L31,MATCH($C$2,$B32:$B34,0),0) -> -0.414846 | M31: =OFFSET(M31,MATCH($C$2,$B32:$B34,0),0) -> -0.414846
B32: Best Case | C32: =C$8/C$5 -> -0.414846 | D32: =D$8/D$5 -> -0.41733914 | E32: =E$8/E$5 -> -0.35139474 | I32: =_xlfn.QUARTILE.EXC($C32:$E32,3) -> -0.35139474 | J32: =_xlfn.QUARTILE.EXC($C32:$E32,3) -> -0.35139474 | K32: =_xlfn.QUARTILE.EXC($C32:$E32,3) -> -0.35139474 | L32: =_xlfn.QUARTILE.EXC($C32:$E32,3) -> -0.35139474 | M32: =_xlfn.QUARTILE.EXC($C32:$E32,3) -> -0.35139474
B33: Base Case | C33: =C$8/C$5 -> -0.414846 | D33: =D$8/D$5 -> -0.41733914 | E33: =E$8/E$5 -> -0.35139474 | I33: =_xlfn.QUARTILE.EXC($C33:$E33,2) -> -0.414846 | J33: =_xlfn.QUARTILE.EXC($C33:$E33,2) -> -0.414846 | K33: =_xlfn.QUARTILE.EXC($C33:$E33,2) -> -0.414846 | L33: =_xlfn.QUARTILE.EXC($C33:$E33,2) -> -0.414846 | M33: =_xlfn.QUARTILE.EXC($C33:$E33,2) -> -0.414846
B34: Worst Case | C34: =C$8/C$5 -> -0.414846 | D34: =D$8/D$5 -> -0.41733914 | E34: =E$8/E$5 -> -0.35139474 | I34: =_xlfn.QUARTILE.EXC($C34:$E34,1) -> -0.41733914 | J34: =_xlfn.QUARTILE.EXC($C34:$E34,1) -> -0.41733914 | K34: =_xlfn.QUARTILE.EXC($C34:$E34,1) -> -0.41733914 | L34: =_xlfn.QUARTILE.EXC($C34:$E34,1) -> -0.41733914 | M34: =_xlfn.QUARTILE.EXC($C34:$E34,1) -> -0.41733914
B36: Taxes % | I36: -0.35 | J36: -0.35 | K36: -0.35 | L36: -0.35 | M36: -0.35

Sheet BS
B1: Balance Sheet
F2: Forecast
B3: $ in million | C3: 42004 | D3: 42369 | E3: 42735 | F3: 43100 | G3: 43465 | H3: 43830 | I3: 44196 | J3: 44561
B4: Trade Receivables | C4: =INDEX('BS 2014'!$B:$D,MATCH(BS!$B4,'BS 2014'!$B:$B,0),MATCH(C$3,'BS 2014'!B$1:D$1,0)) -> 143.9 | D4: =INDEX('BS 2015'!$B:$D,MATCH(BS!$B4,'BS 2015'!$B:$B,0),MATCH(D$3,'BS 2015'!$B$1:$D$1,0)) -> 154.8 | E4: =INDEX('BS 2016'!$B:$E,MATCH(BS!$B4,'BS 2016'!$B:$B,0),MATCH(E$3,'BS 2016'!$B$1:$E$1,0)) -> 169.3 | F4: =F18*'P&L'!I5/360 -> 162.08353 | G4: =G18*'P&L'!J5/360 -> 165.3252 | H4: =H18*'P&L'!K5/360 -> 168.6317 | I4: =I18*'P&L'!L5/360 -> 172.00433 | J4: =J18*'P&L'!M5/360 -> 175.44442
B5: Inventory | C5: =INDEX('BS 2014'!$B:$D,MATCH(BS!$B5,'BS 2014'!$B:$B,0),MATCH(C$3,'BS 2014'!B$1:D$1,0)) -> 85 | D5: =INDEX('BS 2015'!$B:$D,MATCH(BS!$B5,'BS 2015'!$B:$B,0),MATCH(D$3,'BS 2015'!$B$1:$D$1,0)) -> 92 | E5: =INDEX('BS 2016'!$B:$E,MATCH(BS!$B5,'BS 2016'!$B:$B,0),MATCH(E$3,'BS 2016'!$B$1:$E$1,0)) -> 110 | F5: =-F20*'P&L'!I$6/360 -> 99.478948 | G5: =-G20*'P&L'!J$6/360 -> 101.46853 | H5: =-H20*'P&L'!K$6/360 -> 103.4979 | I5: =-I20*'P&L'!L$6/360 -> 105.56786 | J5: =-J20*'P&L'!M$6/360 -> 107.67921
B6: PP&E | C6: =INDEX('BS 2014'!$B:$D,MATCH(BS!$B6,'BS 2014'!$B:$B,0),MATCH(C$3,'BS 2014'!B$1:D$1,0)) -> 632.5 | D6: =INDEX('BS 2015'!$B:$D,MATCH(BS!$B6,'BS 2015'!$B:$B,0),MATCH(D$3,'BS 2015'!$B$1:$D$1,0)) -> 632.5 | E6: =INDEX('BS 2016'!$B:$E,MATCH(BS!$B6,'BS 2016'!$B:$B,0),MATCH(E$3,'BS 2016'!$B$1:$E$1,0)) -> 659.5 | F6: ='Fixed Asset Roll Forward'!F7 -> 673.57628 | G6: ='Fixed Asset Roll Forward'!G7 -> 687.95301 | H6: ='Fixed Asset Roll Forward'!H7 -> 702.63659 | I6: ='Fixed Asset Roll Forward'!I7 -> 717.63358 | J6: ='Fixed Asset Roll Forward'!J7 -> 732.95066
B7: Cash | C7: =INDEX('BS 2014'!$B:$D,MATCH(BS!$B7,'BS 2014'!$B:$B,0),MATCH(C$3,'BS 2014'!B$1:D$1,0)) -> 24.8 | D7: =INDEX('BS 2015'!$B:$D,MATCH(BS!$B7,'BS 2015'!$B:$B,0),MATCH(D$3,'BS 2015'!$B$1:$D$1,0)) -> 21.8 | E7: =INDEX('BS 2016'!$B:$E,MATCH(BS!$B7,'BS 2016'!$B:$B,0),MATCH(E$3,'BS 2016'!$B$1:$E$1,0)) -> 220 | F7: =E7+'Cash Flow'!C18 -> 313.64357 | G7: =F7+'Cash Flow'!D18 -> 364.45545 | H7: =G7+'Cash Flow'!E18 -> 415.12245 | I7: =H7+'Cash Flow'!F18 -> 465.47394 | J7: =I7+'Cash Flow'!G18 -> 515.32086
B8: Other assets | C8: =INDEX('BS 2014'!$B:$D,MATCH(BS!$B8,'BS 2014'!$B:$B,0),MATCH(C$3,'BS 2014'!B$1:D$1,0)) -> 45.9 | D8: =INDEX('BS 2015'!$B:$D,MATCH(BS!$B8,'BS 2015'!$B:$B,0),MATCH(D$3,'BS 2015'!$B$1:$D$1,0)) -> 46.9 | E8: =INDEX('BS 2016'!$B:$E,MATCH(BS!$B8,'BS 2016'!$B:$B,0),MATCH(E$3,'BS 2016'!$B$1:$E$1,0)) -> 68 | F8: =F21*'P&L'!I$5 -> 55.601476 | G8: =G21*'P&L'!J5 -> 56.713506 | H8: =H21*'P&L'!K5 -> 57.847776 | I8: =I21*'P&L'!L5 -> 59.004732 | J8: =J21*'P&L'!M5 -> 60.184826
B9: Asset | C9: =SUM(C4:C8) -> 932.1 | D9: =SUM(D4:D8) -> 948 | E9: =SUM(E4:E8) -> 1226.8 | F9: =SUM(F4:F8) -> 1304.3838 | G9: =SUM(G4:G8) -> 1375.9157 | H9: =SUM(H4:H8) -> 1447.7364 | I9: =SUM(I4:I8) -> 1519.6844 | J9: =SUM(J4:J8) -> 1591.58
B11: Trade Payables | C11: =INDEX('BS 2014'!$B:$D,MATCH(BS!$B11,'BS 2014'!$B:$B,0),MATCH(C$3,'BS 2014'!B$1:D$1,0)) -> 68 | D11: =INDEX('BS 2015'!$B:$D,MATCH(BS!$B11,'BS 2015'!$B:$B,0),MATCH(D$3,'BS 2015'!$B$1:$D$1,0)) -> 68.9 | E11: =INDEX('BS 2016'!$B:$E,MATCH(BS!$B11,'BS 2016'!$B:$B,0),MATCH(E$3,'BS 2016'!$B$1:$E$1,0)) -> 68.9 | F11: =-F19*'P&L'!I$6/360 -> 71.261862 | G11: =-G19*'P&L'!J$6/360 -> 72.6871 | H11: =-H19*'P&L'!K$6/360 -> 74.140842 | I11: =-I19*'P&L'!L$6/360 -> 75.623658 | J11: =-J19*'P&L'!M$6/360 -> 77.136132
B12: Provisions | C12: =INDEX('BS 2014'!$B:$D,MATCH(BS!$B12,'BS 2014'!$B:$B,0),MATCH(C$3,'BS 2014'!B$1:D$1,0)) -> 32.5 | D12: =INDEX('BS 2015'!$B:$D,MATCH(BS!$B12,'BS 2015'!$B:$B,0),MATCH(D$3,'BS 2015'!$B$1:$D$1,0)) -> 28.7 | E12: =INDEX('BS 2016'!$B:$E,MATCH(BS!$B12,'BS 2016'!$B:$B,0),MATCH(E$3,'BS 2016'!$B$1:$E$1,0)) -> 28.7 | F12: =E12 -> 28.7 | G12: =F12 -> 28.7 | H12: =G12 -> 28.7 | I12: =H12 -> 28.7 | J12: =I12 -> 28.7
B13: Financial Liabilities | C13: =INDEX('BS 2014'!$B:$D,MATCH(BS!$B13,'BS 2014'!$B:$B,0),MATCH(C$3,'BS 2014'!B$1:D$1,0)) -> 615.8 | D13: =INDEX('BS 2015'!$B:$D,MATCH(BS!$B13,'BS 2015'!$B:$B,0),MATCH(D$3,'BS 2015'!$B$1:$D$1,0)) -> 610.4 | E13: =INDEX('BS 2016'!$B:$E,MATCH(BS!$B13,'BS 2016'!$B:$B,0),MATCH(E$3,'BS 2016'!$B$1:$E$1,0)) -> 605 | F13: ='Financial Liablity'!F7 -> 565.17885 | G13: ='Financial Liablity'!G7 -> 521.77379 | H13: ='Financial Liablity'!H7 -> 474.46227 | I13: ='Financial Liablity'!I7 -> 422.89272 | J13: ='Financial Liablity'!J7 -> 366.68191
B14: Other liabilities | C14: =INDEX('BS 2014'!$B:$D,MATCH(BS!$B14,'BS 2014'!$B:$B,0),MATCH(C$3,'BS 2014'!B$1:D$1,0)) -> 48.3 | D14: =INDEX('BS 2015'!$B:$D,MATCH(BS!$B14,'BS 2015'!$B:$B,0),MATCH(D$3,'BS 2015'!$B$1:$D$1,0)) -> 43.3 | E14: =INDEX('BS 2016'!$B:$E,MATCH(BS!$B14,'BS 2016'!$B:$B,0),MATCH(E$3,'BS 2016'!$B$1:$E$1,0)) -> 38.9 | F14: =F22*'P&L'!I$5 -> 45.309459 | G14: =G22*'P&L'!J$5 -> 46.215648 | H14: =H22*'P&L'!K$5 -> 47.139961 | I14: =I22*'P&L'!L$5 -> 48.08276 | J14: =J22*'P&L'!M$5 -> 49.044415
B15: Equity | C15: =INDEX('BS 2014'!$B:$D,MATCH(BS!$B15,'BS 2014'!$B:$B,0),MATCH(C$3,'BS 2014'!B$1:D$1,0)) -> 167.5 | D15: =INDEX('BS 2015'!$B:$D,MATCH(BS!$B15,'BS 2015'!$B:$B,0),MATCH(D$3,'BS 2015'!$B$1:$D$1,0)) -> 196.7 | E15: =INDEX('BS 2016'!$B:$E,MATCH(BS!$B15,'BS 2016'!$B:$B,0),MATCH(E$3,'BS 2016'!$B$1:$E$1,0)) -> 485.3 | F15: ='Equity Schedule'!F8 -> 593.93364 | G15: ='Equity Schedule'!G8 -> 706.53916 | H15: ='Equity Schedule'!H8 -> 823.29334 | I15: ='Equity Schedule'!I8 -> 944.3853 | J15: ='Equity Schedule'!J8 -> 1070.0175
B16: Liablity & Equity | C16: =SUM(C11:C15) -> 932.1 | D16: =SUM(D11:D15) -> 948 | E16: =SUM(E11:E15) -> 1226.8 | F16: =SUM(F11:F15) -> 1304.3838 | G16: =SUM(G11:G15) -> 1375.9157 | H16: =SUM(H11:H15) -> 1447.7364 | I16: =SUM(I11:I15) -> 1519.6844 | J16: =SUM(J11:J15) -> 1591.58
B18: DSO | C18: =C4/'P&L'!C5*360 -> 17.728953 | D18: =D4/'P&L'!D5*360 -> 18.675603 | E18: =E4/'P&L'!E5*360 -> 20.048684 | F18: =AVERAGE($C18:$E18) -> 18.817747 | G18: =AVERAGE($C18:$E18) -> 18.817747 | H18: =AVERAGE($C18:$E18) -> 18.817747 | I18: =AVERAGE($C18:$E18) -> 18.817747 | J18: =AVERAGE($C18:$E18) -> 18.817747
B19: DPO | C19: =-1*C11/'P&L'!C$6*360 -> 17.473233 | D19: =-1*D11/'P&L'!D$6*360 -> 17.934924 | E19: =-1*E11/'P&L'!E$6*360 -> 18.144843 | F19: =AVERAGE($C19:$E19) -> 17.851 | G19: =AVERAGE($C19:$E19) -> 17.851 | H19: =AVERAGE($C19:$E19) -> 17.851 | I19: =AVERAGE($C19:$E19) -> 17.851 | J19: =AVERAGE($C19:$E19) -> 17.851
B20: DIO | C20: =-1*C5/'P&L'!C$6*360 -> 21.841542 | D20: =-1*D5/'P&L'!D$6*360 -> 23.947939 | E20: =-1*E5/'P&L'!E$6*360 -> 28.968544 | F20: =AVERAGE($C20:$E20) -> 24.919342 | G20: =AVERAGE($C20:$E20) -> 24.919342 | H20: =AVERAGE($C20:$E20) -> 24.919342 | I20: =AVERAGE($C20:$E20) -> 24.919342 | J20: =AVERAGE($C20:$E20) -> 24.919342
B21: other assets % | C21: =C8/'P&L'!C$5 -> 0.015708419 | D21: =D8/'P&L'!D$5 -> 0.015717158 | E21: =E8/'P&L'!E$5 -> 0.022368421 | F21: =AVERAGE($C21:$E21) -> 0.017931333 | G21: =AVERAGE($C21:$E21) -> 0.017931333 | H21: =AVERAGE($C21:$E21) -> 0.017931333 | I21: =AVERAGE($C21:$E21) -> 0.017931333 | J21: =AVERAGE($C21:$E21) -> 0.017931333
B22: other liablity % | C22: =C14/'P&L'!C$5 -> 0.016529774 | D22: =D14/'P&L'!D$5 -> 0.014510724 | E22: =E14/'P&L'!E$5 -> 0.012796053 | F22: =AVERAGE($C22:$E22) -> 0.014612184 | G22: =AVERAGE($C22:$E22) -> 0.014612184 | H22: =AVERAGE($C22:$E22) -> 0.014612184 | I22: =AVERAGE($C22:$E22) -> 0.014612184 | J22: =AVERAGE($C22:$E22) -> 0.014612184
B25: Check | C25: =C9-C16 -> 0 | D25: =D9-D16 -> 0 | E25: =E9-E16 -> 0 | F25: =F9-F16 -> 0 | G25: =G9-G16 -> 0 | H25: =H9-H16 -> 0 | I25: =I9-I16 -> 0 | J25: =J9-J16 -> 0

Sheet Fixed Asset Roll Forward
B1: Fixed Asset Roll Forward
F2: Forecast
B3: $ in million | C3: 42004 | D3: 42369 | E3: 42735 | F3: 43100 | G3: 43465 | H3: 43830 | I3: 44196 | J3: 44561
B4: Beginning PP&E | D4: =BS!C6 -> 632.5 | E4: =BS!D6 -> 632.5 | F4: =E7 -> 659.5 | G4: =F7 -> 673.57628 | H4: =G7 -> 687.95301 | I4: =H7 -> 702.63659 | J4: =I7 -> 717.63358
B5: D&A | D5: ='P&L'!D10 -> -44 | E5: ='P&L'!E10 -> -41 | F5: =F4*F9 -> -44.314229 | G5: =G4*G9 -> -45.260067 | H5: =H4*H9 -> -46.226092 | I5: =I4*I9 -> -47.212736 | J5: =J4*J9 -> -48.220438
B6: CapeX | D6: =D7-D5-D4 -> 44 | E6: =E7-E5-E4 -> 68 | F6: =F4*F10 -> 58.390514 | G6: =G4*G10 -> 59.636794 | H6: =H4*H10 -> 60.909674 | I6: =I4*I10 -> 62.209722 | J6: =J4*J10 -> 63.537519
B7: Ending PP&E | D7: =BS!D6 -> 632.5 | E7: =BS!E6 -> 659.5 | F7: =SUM(F4:F6) -> 673.57628 | G7: =SUM(G4:G6) -> 687.95301 | H7: =SUM(H4:H6) -> 702.63659 | I7: =SUM(I4:I6) -> 717.63358 | J7: =SUM(J4:J6) -> 732.95066
B9: D&A as a % of beginning PP&E | D9: =D5/D4 -> -0.069565217 | E9: =E5/E4 -> -0.064822134 | F9: =AVERAGE($D9:$E9) -> -0.067193676 | G9: =AVERAGE($D9:$E9) -> -0.067193676 | H9: =AVERAGE($D9:$E9) -> -0.067193676 | I9: =AVERAGE($D9:$E9) -> -0.067193676 | J9: =AVERAGE($D9:$E9) -> -0.067193676
B10: Capex as a % of Beginning PP&E | D10: =D6/D4 -> 0.069565217 | E10: =E6/E4 -> 0.10750988 | F10: =AVERAGE($D10:$E10) -> 0.088537549 | G10: =AVERAGE($D10:$E10) -> 0.088537549 | H10: =AVERAGE($D10:$E10) -> 0.088537549 | I10: =AVERAGE($D10:$E10) -> 0.088537549 | J10: =AVERAGE($D10:$E10) -> 0.088537549

Sheet Financial Liablity
B1: Financial Liablity
F2: Forecast
B3: $ in million | C3: 42004 | D3: 42369 | E3: 42735 | F3: 43100 | G3: 43465 | H3: 43830 | I3: 44196 | J3: 44561
B4: Beginning Debt | D4: =C7 -> 615.8 | E4: =D7 -> 610.4 | F4: =E7 -> 605 | G4: =F7 -> 565.17885 | H4: =G7 -> 521.77379 | I4: =H7 -> 474.46227 | J4: =I7 -> 422.89272
B5: New Debt | D5: 0 | E5: 0 | F5: 0 | G5: 0 | H5: 0 | I5: 0 | J5: 0
B6: Principal Repayment | D6: =D7-D4 -> -5.4 | E6: =E7-E4 -> -5.4 | F6: =C16 -> -39.821154 | G6: =D16 -> -43.405058 | H6: =E16 -> -47.311514 | I6: =F16 -> -51.56955 | J6: =G16 -> -56.210809
B7: Ending Debt | C7: =BS!C13 -> 615.8 | D7: =BS!D13 -> 610.4 | E7: =BS!E13 -> 605 | F7: =SUM(F4:F6) -> 565.17885 | G7: =SUM(G4:G6) -> 521.77379 | H7: =SUM(H4:H6) -> 474.46227 | I7: =SUM(I4:I6) -> 422.89272 | J7: =SUM(J4:J6) -> 366.68191
B9: Debt to repaid in (Year) | C9: 10
B10: Intrest Rate | C10: 0.09
B11: Annual Payment | C11: =PMT(C10,C9,E7) -> -94.271154
B13: Peiord | C13: 1 | D13: 2 | E13: 3 | F13: 4 | G13: 5 | H13: 6 | I13: 7 | J13: 8 | K13: 9 | L13: 10
B14: Payment | C14: =$C$11 -> -94.271154 | D14: =$C$11 -> -94.271154 | E14: =$C$11 -> -94.271154 | F14: =$C$11 -> -94.271154 | G14: =$C$11 -> -94.271154 | H14: =$C$11 -> -94.271154 | I14: =$C$11 -> -94.271154 | J14: =$C$11 -> -94.271154 | ... L14: =$C$11 -> -94.271154
B15: Intrest Exp | C15: =-E7*C10 -> -54.45 | D15: =-C17*$C$10 -> -50.866096 | E15: =-D17*$C$10 -> -46.959641 | F15: =-E17*$C$10 -> -42.701605 | G15: =-F17*$C$10 -> -38.060345 | H15: =-G17*$C$10 -> -33.001372 | I15: =-H17*$C$10 -> -27.487092 | J15: =-I17*$C$10 -> -21.476526 | K15: =-J17*$C$10 -> -14.92501 | L15: =-K17*$C$10 -> -7.7838568
B16: Debt repayment | C16: =C14-C15 -> -39.821154 | D16: =D14-D15 -> -43.405058 | E16: =E14-E15 -> -47.311514 | F16: =F14-F15 -> -51.56955 | G16: =G14-G15 -> -56.210809 | H16: =H14-H15 -> -61.269782 | I16: =I14-I15 -> -66.784062 | J16: =J14-J15 -> -72.794628 | ... L16: =L14-L15 -> -86.487298
B17: Residental Debt | C17: =E7+C16 -> 565.17885 | D17: =C17+D16 -> 521.77379 | E17: =D17+E16 -> 474.46227 | F17: =E17+F16 -> 422.89272 | G17: =F17+G16 -> 366.68191 | H17: =G17+H16 -> 305.41213 | I17: =H17+I16 -> 238.62807 | J17: =I17+J16 -> 165.83344 | K17: =J17+K16 -> 86.487298 | L17: =K17+L16 -> 2.2737368e-13

Sheet Equity Schedule
B1: Equity Schedule
F2: Forecast
B3: $ in million | C3: 42004 | D3: 42369 | E3: 42735 | F3: 43100 | G3: 43465 | H3: 43830 | I3: 44196 | J3: 44561
B4: Beginning Equity | F4: =E8 -> 485.3 | G4: =F8 -> 593.93364 | H4: =G8 -> 706.53916 | I4: =H8 -> 823.29334 | J4: =I8 -> 944.3853
B5: Increase Capital | F5: 0 | G5: 0 | H5: 0 | I5: 0 | J5: 0
B6: Net Income (Loss) | F6: ='P&L'!I15 -> 181.05607 | G6: ='P&L'!J15 -> 187.67587 | H6: ='P&L'!K15 -> 194.5903 | I6: ='P&L'!L15 -> 201.81993 | J6: ='P&L'!M15 -> 209.38703
B7: Dividents | F7: =IF(F6>0,-F6*F10,0) -> -72.422427 | G7: =IF(G6>0,-G6*G10,0) -> -75.070346 | H7: =IF(H6>0,-H6*H10,0) -> -77.836121 | I7: =IF(I6>0,-I6*I10,0) -> -80.727971 | J7: =IF(J6>0,-J6*J10,0) -> -83.75481
B8: Ending Equity | E8: =BS!E15 -> 485.3 | F8: =SUM(F4:F7) -> 593.93364 | G8: =SUM(G4:G7) -> 706.53916 | H8: =SUM(H4:H7) -> 823.29334 | I8: =SUM(I4:I7) -> 944.3853 | J8: =SUM(J4:J7) -> 1070.0175
B10: Divident as 40% of Net Income | F10: 0.4 | G10: 0.4 | H10: 0.4 | I10: 0.4 | J10: 0.4

Sheet Cash Flow
B1: Cash Flow
C2: Forecast
B3: $ in million | C3: 43100 | D3: 43465 | E3: 43830 | F3: 44196 | G3: 44561
B4: EBIDTA | C4: ='P&L'!I9 -> 377.31202 | D4: ='P&L'!J9 -> 384.85826 | E4: ='P&L'!K9 -> 392.55543 | F4: ='P&L'!L9 -> 400.40654 | G4: ='P&L'!M9 -> 408.41467
B5: Intrest Exp | C5: ='P&L'!I12 -> -54.45 | D5: ='P&L'!J12 -> -50.866096 | E5: ='P&L'!K12 -> -46.959641 | F5: ='P&L'!L12 -> -42.701605 | G5: ='P&L'!M12 -> -38.060345
B6: Tax | C6: ='P&L'!I14 -> -97.491728 | D6: ='P&L'!J14 -> -101.05624 | E6: ='P&L'!K14 -> -104.77939 | F6: ='P&L'!L14 -> -108.67227 | G6: ='P&L'!M14 -> -112.74686
B7: Change in Trade receivable | C7: =-(BS!F4-BS!E4) -> 7.2164748 | D7: =-(BS!G4-BS!F4) -> -3.2416705 | E7: =-(BS!H4-BS!G4) -> -3.3065039 | F7: =-(BS!I4-BS!H4) -> -3.372634 | G7: =-(BS!J4-BS!I4) -> -3.4400867
B8: Change in Inventory | C8: =-(BS!F5-BS!E5) -> 10.521052 | D8: =-(BS!G5-BS!F5) -> -1.989579 | E8: =-(BS!H5-BS!G5) -> -2.0293705 | F8: =-(BS!I5-BS!H5) -> -2.0699579 | G8: =-(BS!J5-BS!I5) -> -2.1113571
B9: Change in Trade Payable | C9: =BS!F11-BS!E11 -> 2.3618623 | D9: =BS!G11-BS!F11 -> 1.4252372 | E9: =BS!H11-BS!G11 -> 1.453742 | F9: =BS!I11-BS!H11 -> 1.4828168 | G9: =BS!J11-BS!I11 -> 1.5124732
B10: Change in Other Asset | C10: =-(BS!F8-BS!E8) -> 12.398524 | D10: =-(BS!G8-BS!F8) -> -1.1120295 | E10: =-(BS!H8-BS!G8) -> -1.1342701 | F10: =-(BS!I8-BS!H8) -> -1.1569555 | G10: =-(BS!J8-BS!I8) -> -1.1800946
B11: Change in Other Liablity | C11: =BS!F14-BS!E14 -> 6.4094587 | D11: =BS!G14-BS!F14 -> 0.90618917 | E11: =BS!H14-BS!G14 -> 0.92431296 | F11: =BS!I14-BS!H14 -> 0.94279922 | G11: =BS!J14-BS!I14 -> 0.9616552
B12: Capex | C12: =-'Fixed Asset Roll Forward'!F6 -> -58.390514 | D12: =-'Fixed Asset Roll Forward'!G6 -> -59.636794 | E12: =-'Fixed Asset Roll Forward'!H6 -> -60.909674 | F12: =-'Fixed Asset Roll Forward'!I6 -> -62.209722 | G12: =-'Fixed Asset Roll Forward'!J6 -> -63.537519
B13: Operating Cashflow | C13: =SUM(C4:C12) -> 205.88715 | D13: =SUM(D4:D12) -> 169.28729 | E13: =SUM(E4:E12) -> 175.81463 | F13: =SUM(F4:F12) -> 182.64901 | G13: =SUM(G4:G12) -> 189.81254
B14: Dividents | C14: ='Equity Schedule'!F7 -> -72.422427 | D14: ='Equity Schedule'!G7 -> -75.070346 | E14: ='Equity Schedule'!H7 -> -77.836121 | F14: ='Equity Schedule'!I7 -> -80.727971 | G14: ='Equity Schedule'!J7 -> -83.75481
B15: Change in Finace Liablity | C15: ='Financial Liablity'!F7-'Financial Liablity'!E7 -> -39.821154 | D15: ='Financial Liablity'!G7-'Financial Liablity'!F7 -> -43.405058 | E15: ='Financial Liablity'!H7-'Financial Liablity'!G7 -> -47.311514 | F15: ='Financial Liablity'!I7-'Financial Liablity'!H7 -> -51.56955 | G15: ='Financial Liablity'!J7-'Financial Liablity'!I7 -> -56.210809
B16: Change in Provions | C16: =BS!F12-BS!E12 -> 0 | D16: =BS!G12-BS!F12 -> 0 | E16: =BS!H12-BS!G12 -> 0 | F16: =BS!I12-BS!H12 -> 0 | G16: =BS!J12-BS!I12 -> 0
B17: Change in Equity | C17: ='Equity Schedule'!F8-'Equity Schedule'!E8-'Equity Schedule'!F6-'Equity Schedule'!F7 -> 0 | D17: ='Equity Schedule'!G8-'Equity Schedule'!F8-'Equity Schedule'!G6-'Equity Schedule'!G7 -> 0 | E17: ='Equity Schedule'!H8-'Equity Schedule'!G8-'Equity Schedule'!H6-'Equity Schedule'!H7 -> 0 | F17: ='Equity Schedule'!I8-'Equity Schedule'!H8-'Equity Schedule'!I6-'Equity Schedule'!I7 -> 0 | G17: ='Equity Schedule'!J8-'Equity Schedule'!I8-'Equity Schedule'!J6-'Equity Schedule'!J7 -> 0
B18: Net Cash Flow | C18: =SUM(C13:C17) -> 93.643573 | D18: =SUM(D13:D17) -> 50.811882 | E18: =SUM(E13:E17) -> 50.666997 | F18: =SUM(F13:F17) -> 50.351489 | G18: =SUM(G13:G17) -> 49.846916
